[2024-08-14 20:50:18,534][flwr][INFO] - Starting Flower simulation, config: num_rounds=10, no round_timeout
[2024-08-14 20:50:31,136][flwr][INFO] - Flower VCE: Ray initialized with resources: {'node:128.232.115.66': 1.0, 'node:__internal_head__': 1.0, 'object_store_memory': 69893840486.0, 'memory': 153085627802.0, 'accelerator_type:G': 1.0, 'GPU': 1.0, 'CPU': 56.0}
[2024-08-14 20:50:31,137][flwr][INFO] - Optimize your simulation with Flower VCE: https://flower.ai/docs/framework/how-to-run-simulations.html
[2024-08-14 20:50:31,137][flwr][INFO] - Flower VCE: Resources for each Virtual Client: {'num_cpus': 2, 'num_gpus': 0.0}
[2024-08-14 20:50:31,169][flwr][INFO] - Flower VCE: Creating VirtualClientEngineActorPool with 28 actors
[2024-08-14 20:50:31,171][flwr][INFO] - [INIT]
[2024-08-14 20:50:31,171][flwr][INFO] - Requesting initial parameters from one random client
[2024-08-14 20:50:40,522][flwr][ERROR] - Traceback (most recent call last):
  File "/nfs-share/pa511/.cache/pypoetry/virtualenvs/advanced-pytorch-4G2CGpb3-py3.8/lib/python3.8/site-packages/flwr/simulation/ray_transport/ray_client_proxy.py", line 94, in _submit_job
    out_mssg, updated_context = self.actor_pool.get_client_result(
  File "/nfs-share/pa511/.cache/pypoetry/virtualenvs/advanced-pytorch-4G2CGpb3-py3.8/lib/python3.8/site-packages/flwr/simulation/ray_transport/ray_actor.py", line 398, in get_client_result
    return self._fetch_future_result(cid)
  File "/nfs-share/pa511/.cache/pypoetry/virtualenvs/advanced-pytorch-4G2CGpb3-py3.8/lib/python3.8/site-packages/flwr/simulation/ray_transport/ray_actor.py", line 279, in _fetch_future_result
    res_cid, out_mssg, updated_context = ray.get(
  File "/nfs-share/pa511/.cache/pypoetry/virtualenvs/advanced-pytorch-4G2CGpb3-py3.8/lib/python3.8/site-packages/ray/_private/auto_init_hook.py", line 21, in auto_init_wrapper
    return fn(*args, **kwargs)
  File "/nfs-share/pa511/.cache/pypoetry/virtualenvs/advanced-pytorch-4G2CGpb3-py3.8/lib/python3.8/site-packages/ray/_private/client_mode_hook.py", line 103, in wrapper
    return func(*args, **kwargs)
  File "/nfs-share/pa511/.cache/pypoetry/virtualenvs/advanced-pytorch-4G2CGpb3-py3.8/lib/python3.8/site-packages/ray/_private/worker.py", line 2667, in get
    values, debugger_breakpoint = worker.get_objects(object_refs, timeout=timeout)
  File "/nfs-share/pa511/.cache/pypoetry/virtualenvs/advanced-pytorch-4G2CGpb3-py3.8/lib/python3.8/site-packages/ray/_private/worker.py", line 864, in get_objects
    raise value.as_instanceof_cause()
ray.exceptions.RayTaskError(ClientAppException): [36mray::ClientAppActor.run()[39m (pid=3890685, ip=128.232.115.66, actor_id=b9bdd3a5eb3d22272d89f49f01000000, repr=<flwr.simulation.ray_transport.ray_actor.ClientAppActor object at 0x7fc1ec6b2310>)
  File "/nfs-share/pa511/.cache/pypoetry/virtualenvs/advanced-pytorch-4G2CGpb3-py3.8/lib/python3.8/site-packages/flwr/client/client_app.py", line 143, in __call__
    return self._call(message, context)
  File "/nfs-share/pa511/.cache/pypoetry/virtualenvs/advanced-pytorch-4G2CGpb3-py3.8/lib/python3.8/site-packages/flwr/client/client_app.py", line 126, in ffn
    out_message = handle_legacy_message_from_msgtype(
  File "/nfs-share/pa511/.cache/pypoetry/virtualenvs/advanced-pytorch-4G2CGpb3-py3.8/lib/python3.8/site-packages/flwr/client/message_handler/message_handler.py", line 120, in handle_legacy_message_from_msgtype
    get_parameters_res = maybe_call_get_parameters(
  File "/nfs-share/pa511/.cache/pypoetry/virtualenvs/advanced-pytorch-4G2CGpb3-py3.8/lib/python3.8/site-packages/flwr/client/client.py", line 214, in maybe_call_get_parameters
    return client.get_parameters(get_parameters_ins)
  File "/nfs-share/pa511/.cache/pypoetry/virtualenvs/advanced-pytorch-4G2CGpb3-py3.8/lib/python3.8/site-packages/flwr/client/numpy_client.py", line 225, in _get_parameters
    parameters = self.numpy_client.get_parameters(config=ins.config)  # type: ignore
  File "/nfs-share/pa511/resnet/client.py", line 54, in get_parameters
    c1 = pyzfp.compress(
  File "pyzfp.pyx", line 174, in pyzfp.compress
AssertionError

The above exception was the direct cause of the following exception:

[36mray::ClientAppActor.run()[39m (pid=3890685, ip=128.232.115.66, actor_id=b9bdd3a5eb3d22272d89f49f01000000, repr=<flwr.simulation.ray_transport.ray_actor.ClientAppActor object at 0x7fc1ec6b2310>)
  File "/nfs-share/pa511/.cache/pypoetry/virtualenvs/advanced-pytorch-4G2CGpb3-py3.8/lib/python3.8/site-packages/flwr/simulation/ray_transport/ray_actor.py", line 63, in run
    raise ClientAppException(str(ex)) from ex
flwr.client.client_app.ClientAppException: 
Exception ClientAppException occurred. Message:

[2024-08-14 20:50:40,523][flwr][ERROR] - [36mray::ClientAppActor.run()[39m (pid=3890685, ip=128.232.115.66, actor_id=b9bdd3a5eb3d22272d89f49f01000000, repr=<flwr.simulation.ray_transport.ray_actor.ClientAppActor object at 0x7fc1ec6b2310>)
  File "/nfs-share/pa511/.cache/pypoetry/virtualenvs/advanced-pytorch-4G2CGpb3-py3.8/lib/python3.8/site-packages/flwr/client/client_app.py", line 143, in __call__
    return self._call(message, context)
  File "/nfs-share/pa511/.cache/pypoetry/virtualenvs/advanced-pytorch-4G2CGpb3-py3.8/lib/python3.8/site-packages/flwr/client/client_app.py", line 126, in ffn
    out_message = handle_legacy_message_from_msgtype(
  File "/nfs-share/pa511/.cache/pypoetry/virtualenvs/advanced-pytorch-4G2CGpb3-py3.8/lib/python3.8/site-packages/flwr/client/message_handler/message_handler.py", line 120, in handle_legacy_message_from_msgtype
    get_parameters_res = maybe_call_get_parameters(
  File "/nfs-share/pa511/.cache/pypoetry/virtualenvs/advanced-pytorch-4G2CGpb3-py3.8/lib/python3.8/site-packages/flwr/client/client.py", line 214, in maybe_call_get_parameters
    return client.get_parameters(get_parameters_ins)
  File "/nfs-share/pa511/.cache/pypoetry/virtualenvs/advanced-pytorch-4G2CGpb3-py3.8/lib/python3.8/site-packages/flwr/client/numpy_client.py", line 225, in _get_parameters
    parameters = self.numpy_client.get_parameters(config=ins.config)  # type: ignore
  File "/nfs-share/pa511/resnet/client.py", line 54, in get_parameters
    c1 = pyzfp.compress(
  File "pyzfp.pyx", line 174, in pyzfp.compress
AssertionError

The above exception was the direct cause of the following exception:

[36mray::ClientAppActor.run()[39m (pid=3890685, ip=128.232.115.66, actor_id=b9bdd3a5eb3d22272d89f49f01000000, repr=<flwr.simulation.ray_transport.ray_actor.ClientAppActor object at 0x7fc1ec6b2310>)
  File "/nfs-share/pa511/.cache/pypoetry/virtualenvs/advanced-pytorch-4G2CGpb3-py3.8/lib/python3.8/site-packages/flwr/simulation/ray_transport/ray_actor.py", line 63, in run
    raise ClientAppException(str(ex)) from ex
flwr.client.client_app.ClientAppException: 
Exception ClientAppException occurred. Message:
[2024-08-14 20:50:40,523][flwr][ERROR] - [36mray::ClientAppActor.run()[39m (pid=3890685, ip=128.232.115.66, actor_id=b9bdd3a5eb3d22272d89f49f01000000, repr=<flwr.simulation.ray_transport.ray_actor.ClientAppActor object at 0x7fc1ec6b2310>)
  File "/nfs-share/pa511/.cache/pypoetry/virtualenvs/advanced-pytorch-4G2CGpb3-py3.8/lib/python3.8/site-packages/flwr/client/client_app.py", line 143, in __call__
    return self._call(message, context)
  File "/nfs-share/pa511/.cache/pypoetry/virtualenvs/advanced-pytorch-4G2CGpb3-py3.8/lib/python3.8/site-packages/flwr/client/client_app.py", line 126, in ffn
    out_message = handle_legacy_message_from_msgtype(
  File "/nfs-share/pa511/.cache/pypoetry/virtualenvs/advanced-pytorch-4G2CGpb3-py3.8/lib/python3.8/site-packages/flwr/client/message_handler/message_handler.py", line 120, in handle_legacy_message_from_msgtype
    get_parameters_res = maybe_call_get_parameters(
  File "/nfs-share/pa511/.cache/pypoetry/virtualenvs/advanced-pytorch-4G2CGpb3-py3.8/lib/python3.8/site-packages/flwr/client/client.py", line 214, in maybe_call_get_parameters
    return client.get_parameters(get_parameters_ins)
  File "/nfs-share/pa511/.cache/pypoetry/virtualenvs/advanced-pytorch-4G2CGpb3-py3.8/lib/python3.8/site-packages/flwr/client/numpy_client.py", line 225, in _get_parameters
    parameters = self.numpy_client.get_parameters(config=ins.config)  # type: ignore
  File "/nfs-share/pa511/resnet/client.py", line 54, in get_parameters
    c1 = pyzfp.compress(
  File "pyzfp.pyx", line 174, in pyzfp.compress
AssertionError

The above exception was the direct cause of the following exception:

[36mray::ClientAppActor.run()[39m (pid=3890685, ip=128.232.115.66, actor_id=b9bdd3a5eb3d22272d89f49f01000000, repr=<flwr.simulation.ray_transport.ray_actor.ClientAppActor object at 0x7fc1ec6b2310>)
  File "/nfs-share/pa511/.cache/pypoetry/virtualenvs/advanced-pytorch-4G2CGpb3-py3.8/lib/python3.8/site-packages/flwr/simulation/ray_transport/ray_actor.py", line 63, in run
    raise ClientAppException(str(ex)) from ex
flwr.client.client_app.ClientAppException: 
Exception ClientAppException occurred. Message:
[2024-08-14 20:50:40,526][flwr][ERROR] - Traceback (most recent call last):
  File "/nfs-share/pa511/.cache/pypoetry/virtualenvs/advanced-pytorch-4G2CGpb3-py3.8/lib/python3.8/site-packages/flwr/simulation/app.py", line 339, in start_simulation
    hist = run_fl(
  File "/nfs-share/pa511/.cache/pypoetry/virtualenvs/advanced-pytorch-4G2CGpb3-py3.8/lib/python3.8/site-packages/flwr/server/server.py", line 490, in run_fl
    hist, elapsed_time = server.fit(
  File "/nfs-share/pa511/.cache/pypoetry/virtualenvs/advanced-pytorch-4G2CGpb3-py3.8/lib/python3.8/site-packages/flwr/server/server.py", line 93, in fit
    self.parameters = self._get_initial_parameters(server_round=0, timeout=timeout)
  File "/nfs-share/pa511/.cache/pypoetry/virtualenvs/advanced-pytorch-4G2CGpb3-py3.8/lib/python3.8/site-packages/flwr/server/server.py", line 282, in _get_initial_parameters
    get_parameters_res = random_client.get_parameters(
  File "/nfs-share/pa511/.cache/pypoetry/virtualenvs/advanced-pytorch-4G2CGpb3-py3.8/lib/python3.8/site-packages/flwr/simulation/ray_transport/ray_client_proxy.py", line 168, in get_parameters
    message_out = self._submit_job(message, timeout)
  File "/nfs-share/pa511/.cache/pypoetry/virtualenvs/advanced-pytorch-4G2CGpb3-py3.8/lib/python3.8/site-packages/flwr/simulation/ray_transport/ray_client_proxy.py", line 108, in _submit_job
    raise ex
  File "/nfs-share/pa511/.cache/pypoetry/virtualenvs/advanced-pytorch-4G2CGpb3-py3.8/lib/python3.8/site-packages/flwr/simulation/ray_transport/ray_client_proxy.py", line 94, in _submit_job
    out_mssg, updated_context = self.actor_pool.get_client_result(
  File "/nfs-share/pa511/.cache/pypoetry/virtualenvs/advanced-pytorch-4G2CGpb3-py3.8/lib/python3.8/site-packages/flwr/simulation/ray_transport/ray_actor.py", line 398, in get_client_result
    return self._fetch_future_result(cid)
  File "/nfs-share/pa511/.cache/pypoetry/virtualenvs/advanced-pytorch-4G2CGpb3-py3.8/lib/python3.8/site-packages/flwr/simulation/ray_transport/ray_actor.py", line 279, in _fetch_future_result
    res_cid, out_mssg, updated_context = ray.get(
  File "/nfs-share/pa511/.cache/pypoetry/virtualenvs/advanced-pytorch-4G2CGpb3-py3.8/lib/python3.8/site-packages/ray/_private/auto_init_hook.py", line 21, in auto_init_wrapper
    return fn(*args, **kwargs)
  File "/nfs-share/pa511/.cache/pypoetry/virtualenvs/advanced-pytorch-4G2CGpb3-py3.8/lib/python3.8/site-packages/ray/_private/client_mode_hook.py", line 103, in wrapper
    return func(*args, **kwargs)
  File "/nfs-share/pa511/.cache/pypoetry/virtualenvs/advanced-pytorch-4G2CGpb3-py3.8/lib/python3.8/site-packages/ray/_private/worker.py", line 2667, in get
    values, debugger_breakpoint = worker.get_objects(object_refs, timeout=timeout)
  File "/nfs-share/pa511/.cache/pypoetry/virtualenvs/advanced-pytorch-4G2CGpb3-py3.8/lib/python3.8/site-packages/ray/_private/worker.py", line 864, in get_objects
    raise value.as_instanceof_cause()
ray.exceptions.RayTaskError(ClientAppException): [36mray::ClientAppActor.run()[39m (pid=3890685, ip=128.232.115.66, actor_id=b9bdd3a5eb3d22272d89f49f01000000, repr=<flwr.simulation.ray_transport.ray_actor.ClientAppActor object at 0x7fc1ec6b2310>)
  File "/nfs-share/pa511/.cache/pypoetry/virtualenvs/advanced-pytorch-4G2CGpb3-py3.8/lib/python3.8/site-packages/flwr/client/client_app.py", line 143, in __call__
    return self._call(message, context)
  File "/nfs-share/pa511/.cache/pypoetry/virtualenvs/advanced-pytorch-4G2CGpb3-py3.8/lib/python3.8/site-packages/flwr/client/client_app.py", line 126, in ffn
    out_message = handle_legacy_message_from_msgtype(
  File "/nfs-share/pa511/.cache/pypoetry/virtualenvs/advanced-pytorch-4G2CGpb3-py3.8/lib/python3.8/site-packages/flwr/client/message_handler/message_handler.py", line 120, in handle_legacy_message_from_msgtype
    get_parameters_res = maybe_call_get_parameters(
  File "/nfs-share/pa511/.cache/pypoetry/virtualenvs/advanced-pytorch-4G2CGpb3-py3.8/lib/python3.8/site-packages/flwr/client/client.py", line 214, in maybe_call_get_parameters
    return client.get_parameters(get_parameters_ins)
  File "/nfs-share/pa511/.cache/pypoetry/virtualenvs/advanced-pytorch-4G2CGpb3-py3.8/lib/python3.8/site-packages/flwr/client/numpy_client.py", line 225, in _get_parameters
    parameters = self.numpy_client.get_parameters(config=ins.config)  # type: ignore
  File "/nfs-share/pa511/resnet/client.py", line 54, in get_parameters
    c1 = pyzfp.compress(
  File "pyzfp.pyx", line 174, in pyzfp.compress
AssertionError

The above exception was the direct cause of the following exception:

[36mray::ClientAppActor.run()[39m (pid=3890685, ip=128.232.115.66, actor_id=b9bdd3a5eb3d22272d89f49f01000000, repr=<flwr.simulation.ray_transport.ray_actor.ClientAppActor object at 0x7fc1ec6b2310>)
  File "/nfs-share/pa511/.cache/pypoetry/virtualenvs/advanced-pytorch-4G2CGpb3-py3.8/lib/python3.8/site-packages/flwr/simulation/ray_transport/ray_actor.py", line 63, in run
    raise ClientAppException(str(ex)) from ex
flwr.client.client_app.ClientAppException: 
Exception ClientAppException occurred. Message:

[2024-08-14 20:50:40,527][flwr][ERROR] - Your simulation crashed :(. This could be because of several reasons. The most common are: 
	 > Sometimes, issues in the simulation code itself can cause crashes. It's always a good idea to double-check your code for any potential bugs or inconsistencies that might be contributing to the problem. For example: 
		 - You might be using a class attribute in your clients that hasn't been defined.
		 - There could be an incorrect method call to a 3rd party library (e.g., PyTorch).
		 - The return types of methods in your clients/strategies might be incorrect.
	 > Your system couldn't fit a single VirtualClient: try lowering `client_resources`.
	 > All the actors in your pool crashed. This could be because: 
		 - You clients hit an out-of-memory (OOM) error and actors couldn't recover from it. Try launching your simulation with more generous `client_resources` setting (i.e. it seems {'num_cpus': 2, 'num_gpus': 0.0} is not enough for your run). Use fewer concurrent actors. 
		 - You were running a multi-node simulation and all worker nodes disconnected. The head node might still be alive but cannot accommodate any actor with resources: {'num_cpus': 2, 'num_gpus': 0.0}.
Take a look at the Flower simulation examples for guidance <https://flower.ai/docs/framework/how-to-run-simulations.html>.
