/nfs-share/pa511/.cache/pypoetry/virtualenvs/advanced-pytorch-4G2CGpb3-py3.8/lib/python3.8/site-packages/hydra/_internal/defaults_list.py:251: UserWarning: In 'base': Defaults list is missing `_self_`. See https://hydra.cc/docs/1.2/upgrades/1.0_to_1.1/default_composition_order for more information
  warnings.warn(msg, UserWarning)
[92mINFO [0m:      Starting Flower simulation, config: num_rounds=10, no round_timeout
model:
  _target_: torchvision.models.resnet18
  num_classes: ${foo}
strategy:
  _target_: flwr.server.strategy.FedAvg
  fraction_fit: 1.0e-05
  min_fit_clients: ${num_clients_per_round_fit}
  fraction_evaluate: 1.0e-05
  min_evaluate_clients: ${num_clients_per_round_eval}
  min_available_clients: ${num_clients}
  on_fit_config_fn:
    _target_: server.get_on_fit_config
    config: ${config_fit}
foo: 10
num_rounds: 10
num_clients: 100
batch_size: 20
num_classes: 10
num_clients_per_round_fit: 10
num_clients_per_round_eval: 25
config_fit:
  lr: 0.01
  momentum: 0.9
  local_epochs: 1
method:
  name: zpf
  tolerance: 0.001
  precision: 0.1
  rate: 0.1

Files already downloaded and verified
Files already downloaded and verified
[2024-08-14 20:45:42,363][flwr][INFO] - Starting Flower simulation, config: num_rounds=10, no round_timeout
2024-08-14 20:45:45,429	INFO worker.py:1752 -- Started a local Ray instance.
[92mINFO [0m:      Flower VCE: Ray initialized with resources: {'node:__internal_head__': 1.0, 'CPU': 56.0, 'memory': 153956192871.0, 'GPU': 1.0, 'accelerator_type:G': 1.0, 'node:128.232.115.66': 1.0, 'object_store_memory': 70266939801.0}
[2024-08-14 20:45:51,513][flwr][INFO] - Flower VCE: Ray initialized with resources: {'node:__internal_head__': 1.0, 'CPU': 56.0, 'memory': 153956192871.0, 'GPU': 1.0, 'accelerator_type:G': 1.0, 'node:128.232.115.66': 1.0, 'object_store_memory': 70266939801.0}
[92mINFO [0m:      Optimize your simulation with Flower VCE: https://flower.ai/docs/framework/how-to-run-simulations.html
[2024-08-14 20:45:51,514][flwr][INFO] - Optimize your simulation with Flower VCE: https://flower.ai/docs/framework/how-to-run-simulations.html
[92mINFO [0m:      Flower VCE: Resources for each Virtual Client: {'num_cpus': 2, 'num_gpus': 0.0}
[2024-08-14 20:45:51,515][flwr][INFO] - Flower VCE: Resources for each Virtual Client: {'num_cpus': 2, 'num_gpus': 0.0}
[92mINFO [0m:      Flower VCE: Creating VirtualClientEngineActorPool with 28 actors
[2024-08-14 20:45:51,547][flwr][INFO] - Flower VCE: Creating VirtualClientEngineActorPool with 28 actors
[92mINFO [0m:      [INIT]
[2024-08-14 20:45:51,548][flwr][INFO] - [INIT]
[92mINFO [0m:      Requesting initial parameters from one random client
[2024-08-14 20:45:51,549][flwr][INFO] - Requesting initial parameters from one random client
[33m(raylet)[0m [2024-08-14 20:45:55,345 E 3866380 3866410] (raylet) file_system_monitor.cc:111: /tmp/ray/session_2024-08-14_20-45-42_465226_3866120 is over 95% full, available space: 15679328256; capacity: 2015100878848. Object creation will fail if spilling is required.
[36m(ClientAppActor pid=3869578)[0m [93mWARNING [0m:   DEPRECATED FEATURE: `client_fn` now expects a signature `def client_fn(context: Context)`.The provided `client_fn` has signature: {'cid': <Parameter "cid: str">}. You can import the `Context` like this: `from flwr.common import Context`
[36m(ClientAppActor pid=3869578)[0m 
[36m(ClientAppActor pid=3869578)[0m             This is a deprecated feature. It will be removed
[36m(ClientAppActor pid=3869578)[0m             entirely in future versions of Flower.
[36m(ClientAppActor pid=3869578)[0m         
[91mERROR [0m:     Traceback (most recent call last):
  File "/nfs-share/pa511/.cache/pypoetry/virtualenvs/advanced-pytorch-4G2CGpb3-py3.8/lib/python3.8/site-packages/flwr/simulation/ray_transport/ray_client_proxy.py", line 94, in _submit_job
    out_mssg, updated_context = self.actor_pool.get_client_result(
  File "/nfs-share/pa511/.cache/pypoetry/virtualenvs/advanced-pytorch-4G2CGpb3-py3.8/lib/python3.8/site-packages/flwr/simulation/ray_transport/ray_actor.py", line 398, in get_client_result
    return self._fetch_future_result(cid)
  File "/nfs-share/pa511/.cache/pypoetry/virtualenvs/advanced-pytorch-4G2CGpb3-py3.8/lib/python3.8/site-packages/flwr/simulation/ray_transport/ray_actor.py", line 279, in _fetch_future_result
    res_cid, out_mssg, updated_context = ray.get(
  File "/nfs-share/pa511/.cache/pypoetry/virtualenvs/advanced-pytorch-4G2CGpb3-py3.8/lib/python3.8/site-packages/ray/_private/auto_init_hook.py", line 21, in auto_init_wrapper
    return fn(*args, **kwargs)
  File "/nfs-share/pa511/.cache/pypoetry/virtualenvs/advanced-pytorch-4G2CGpb3-py3.8/lib/python3.8/site-packages/ray/_private/client_mode_hook.py", line 103, in wrapper
    return func(*args, **kwargs)
  File "/nfs-share/pa511/.cache/pypoetry/virtualenvs/advanced-pytorch-4G2CGpb3-py3.8/lib/python3.8/site-packages/ray/_private/worker.py", line 2667, in get
    values, debugger_breakpoint = worker.get_objects(object_refs, timeout=timeout)
  File "/nfs-share/pa511/.cache/pypoetry/virtualenvs/advanced-pytorch-4G2CGpb3-py3.8/lib/python3.8/site-packages/ray/_private/worker.py", line 864, in get_objects
    raise value.as_instanceof_cause()
ray.exceptions.RayTaskError(ClientAppException): [36mray::ClientAppActor.run()[39m (pid=3869578, ip=128.232.115.66, actor_id=31e16f17189adc1fe4af8d3401000000, repr=<flwr.simulation.ray_transport.ray_actor.ClientAppActor object at 0x7f6b68332400>)
  File "/nfs-share/pa511/.cache/pypoetry/virtualenvs/advanced-pytorch-4G2CGpb3-py3.8/lib/python3.8/site-packages/flwr/client/client_app.py", line 143, in __call__
    return self._call(message, context)
  File "/nfs-share/pa511/.cache/pypoetry/virtualenvs/advanced-pytorch-4G2CGpb3-py3.8/lib/python3.8/site-packages/flwr/client/client_app.py", line 126, in ffn
    out_message = handle_legacy_message_from_msgtype(
  File "/nfs-share/pa511/.cache/pypoetry/virtualenvs/advanced-pytorch-4G2CGpb3-py3.8/lib/python3.8/site-packages/flwr/client/message_handler/message_handler.py", line 120, in handle_legacy_message_from_msgtype
    get_parameters_res = maybe_call_get_parameters(
  File "/nfs-share/pa511/.cache/pypoetry/virtualenvs/advanced-pytorch-4G2CGpb3-py3.8/lib/python3.8/site-packages/flwr/client/client.py", line 214, in maybe_call_get_parameters
    return client.get_parameters(get_parameters_ins)
  File "/nfs-share/pa511/.cache/pypoetry/virtualenvs/advanced-pytorch-4G2CGpb3-py3.8/lib/python3.8/site-packages/flwr/client/numpy_client.py", line 225, in _get_parameters
    parameters = self.numpy_client.get_parameters(config=ins.config)  # type: ignore
  File "/nfs-share/pa511/resnet/client.py", line 87, in get_parameters
    elif self.cfg.method.acc == "quantize":
[2024-08-14 20:45:59,909][flwr][ERROR] - Traceback (most recent call last):
  File "/nfs-share/pa511/.cache/pypoetry/virtualenvs/advanced-pytorch-4G2CGpb3-py3.8/lib/python3.8/site-packages/flwr/simulation/ray_transport/ray_client_proxy.py", line 94, in _submit_job
    out_mssg, updated_context = self.actor_pool.get_client_result(
  File "/nfs-share/pa511/.cache/pypoetry/virtualenvs/advanced-pytorch-4G2CGpb3-py3.8/lib/python3.8/site-packages/flwr/simulation/ray_transport/ray_actor.py", line 398, in get_client_result
    return self._fetch_future_result(cid)
  File "/nfs-share/pa511/.cache/pypoetry/virtualenvs/advanced-pytorch-4G2CGpb3-py3.8/lib/python3.8/site-packages/flwr/simulation/ray_transport/ray_actor.py", line 279, in _fetch_future_result
    res_cid, out_mssg, updated_context = ray.get(
  File "/nfs-share/pa511/.cache/pypoetry/virtualenvs/advanced-pytorch-4G2CGpb3-py3.8/lib/python3.8/site-packages/ray/_private/auto_init_hook.py", line 21, in auto_init_wrapper
    return fn(*args, **kwargs)
  File "/nfs-share/pa511/.cache/pypoetry/virtualenvs/advanced-pytorch-4G2CGpb3-py3.8/lib/python3.8/site-packages/ray/_private/client_mode_hook.py", line 103, in wrapper
    return func(*args, **kwargs)
  File "/nfs-share/pa511/.cache/pypoetry/virtualenvs/advanced-pytorch-4G2CGpb3-py3.8/lib/python3.8/site-packages/ray/_private/worker.py", line 2667, in get
    values, debugger_breakpoint = worker.get_objects(object_refs, timeout=timeout)
  File "/nfs-share/pa511/.cache/pypoetry/virtualenvs/advanced-pytorch-4G2CGpb3-py3.8/lib/python3.8/site-packages/ray/_private/worker.py", line 864, in get_objects
    raise value.as_instanceof_cause()
ray.exceptions.RayTaskError(ClientAppException): [36mray::ClientAppActor.run()[39m (pid=3869578, ip=128.232.115.66, actor_id=31e16f17189adc1fe4af8d3401000000, repr=<flwr.simulation.ray_transport.ray_actor.ClientAppActor object at 0x7f6b68332400>)
  File "/nfs-share/pa511/.cache/pypoetry/virtualenvs/advanced-pytorch-4G2CGpb3-py3.8/lib/python3.8/site-packages/flwr/client/client_app.py", line 143, in __call__
    return self._call(message, context)
  File "/nfs-share/pa511/.cache/pypoetry/virtualenvs/advanced-pytorch-4G2CGpb3-py3.8/lib/python3.8/site-packages/flwr/client/client_app.py", line 126, in ffn
    out_message = handle_legacy_message_from_msgtype(
  File "/nfs-share/pa511/.cache/pypoetry/virtualenvs/advanced-pytorch-4G2CGpb3-py3.8/lib/python3.8/site-packages/flwr/client/message_handler/message_handler.py", line 120, in handle_legacy_message_from_msgtype
    get_parameters_res = maybe_call_get_parameters(
  File "/nfs-share/pa511/.cache/pypoetry/virtualenvs/advanced-pytorch-4G2CGpb3-py3.8/lib/python3.8/site-packages/flwr/client/client.py", line 214, in maybe_call_get_parameters
    return client.get_parameters(get_parameters_ins)
  File "/nfs-share/pa511/.cache/pypoetry/virtualenvs/advanced-pytorch-4G2CGpb3-py3.8/lib/python3.8/site-packages/flwr/client/numpy_client.py", line 225, in _get_parameters
    parameters = self.numpy_client.get_parameters(config=ins.config)  # type: ignore
  File "/nfs-share/pa511/resnet/client.py", line 87, in get_parameters
    elif self.cfg.method.acc == "quantize":
  File "/nfs-share/pa511/.cache/pypoetry/virtualenvs/advanced-pytorch-4G2CGpb3-py3.8/lib/python3.8/site-packages/omegaconf/dictconfig.py", line 359, in __getattr__
    self._format_and_raise(key=key, value=None, cause=e)
  File "/nfs-share/pa511/.cache/pypoetry/virtualenvs/advanced-pytorch-4G2CGpb3-py3.8/lib/python3.8/site-packages/omegaconf/base.py", line 231, in _format_and_raise
    format_and_raise(
  File "/nfs-share/pa511/.cache/pypoetry/virtualenvs/advanced-pytorch-4G2CGpb3-py3.8/lib/python3.8/site-packages/omegaconf/_utils.py", line 819, in format_and_raise
    _raise(ex, cause)
  File "/nfs-share/pa511/.cache/pypoetry/virtualenvs/advanced-pytorch-4G2CGpb3-py3.8/lib/python3.8/site-packages/omegaconf/_utils.py", line 797, in _raise
    raise ex.with_traceback(sys.exc_info()[2])  # set env var OC_CAUSE=1 for full trace
  File "/nfs-share/pa511/.cache/pypoetry/virtualenvs/advanced-pytorch-4G2CGpb3-py3.8/lib/python3.8/site-packages/omegaconf/dictconfig.py", line 359, in __getattr__
    self._format_and_raise(key=key, value=None, cause=e)
  File "/nfs-share/pa511/.cache/pypoetry/virtualenvs/advanced-pytorch-4G2CGpb3-py3.8/lib/python3.8/site-packages/omegaconf/base.py", line 231, in _format_and_raise
    format_and_raise(
  File "/nfs-share/pa511/.cache/pypoetry/virtualenvs/advanced-pytorch-4G2CGpb3-py3.8/lib/python3.8/site-packages/omegaconf/_utils.py", line 819, in format_and_raise
    _raise(ex, cause)
  File "/nfs-share/pa511/.cache/pypoetry/virtualenvs/advanced-pytorch-4G2CGpb3-py3.8/lib/python3.8/site-packages/omegaconf/_utils.py", line 797, in _raise
    raise ex.with_traceback(sys.exc_info()[2])  # set env var OC_CAUSE=1 for full trace
  File "/nfs-share/pa511/.cache/pypoetry/virtualenvs/advanced-pytorch-4G2CGpb3-py3.8/lib/python3.8/site-packages/omegaconf/dictconfig.py", line 351, in __getattr__
    return self._get_impl(
  File "/nfs-share/pa511/.cache/pypoetry/virtualenvs/advanced-pytorch-4G2CGpb3-py3.8/lib/python3.8/site-packages/omegaconf/dictconfig.py", line 442, in _get_impl
    node = self._get_child(
  File "/nfs-share/pa511/.cache/pypoetry/virtualenvs/advanced-pytorch-4G2CGpb3-py3.8/lib/python3.8/site-packages/omegaconf/basecontainer.py", line 73, in _get_child
    child = self._get_node(
  File "/nfs-share/pa511/.cache/pypoetry/virtualenvs/advanced-pytorch-4G2CGpb3-py3.8/lib/python3.8/site-packages/omegaconf/dictconfig.py", line 475, in _get_node
    self._validate_get(key)
  File "/nfs-share/pa511/.cache/pypoetry/virtualenvs/advanced-pytorch-4G2CGpb3-py3.8/lib/python3.8/site-packages/omegaconf/dictconfig.py", line 164, in _validate_get
    self._format_and_raise(
  File "/nfs-share/pa511/.cache/pypoetry/virtualenvs/advanced-pytorch-4G2CGpb3-py3.8/lib/python3.8/site-packages/omegaconf/base.py", line 231, in _format_and_raise
    format_and_raise(
  File "/nfs-share/pa511/.cache/pypoetry/virtualenvs/advanced-pytorch-4G2CGpb3-py3.8/lib/python3.8/site-packages/omegaconf/_utils.py", line 899, in format_and_raise
    _raise(ex, cause)
  File "/nfs-share/pa511/.cache/pypoetry/virtualenvs/advanced-pytorch-4G2CGpb3-py3.8/lib/python3.8/site-packages/omegaconf/_utils.py", line 797, in _raise
    raise ex.with_traceback(sys.exc_info()[2])  # set env var OC_CAUSE=1 for full trace
omegaconf.errors.ConfigAttributeError: Key 'acc' is not in struct
    full_key: method.acc
    object_type=dict

The above exception was the direct cause of the following exception:

[36mray::ClientAppActor.run()[39m (pid=3869578, ip=128.232.115.66, actor_id=31e16f17189adc1fe4af8d3401000000, repr=<flwr.simulation.ray_transport.ray_actor.ClientAppActor object at 0x7f6b68332400>)
  File "/nfs-share/pa511/.cache/pypoetry/virtualenvs/advanced-pytorch-4G2CGpb3-py3.8/lib/python3.8/site-packages/flwr/simulation/ray_transport/ray_actor.py", line 63, in run
    raise ClientAppException(str(ex)) from ex
flwr.client.client_app.ClientAppException: 
Exception ClientAppException occurred. Message: Key 'acc' is not in struct
    full_key: method.acc
    object_type=dict

  File "/nfs-share/pa511/.cache/pypoetry/virtualenvs/advanced-pytorch-4G2CGpb3-py3.8/lib/python3.8/site-packages/omegaconf/dictconfig.py", line 351, in __getattr__
    return self._get_impl(
  File "/nfs-share/pa511/.cache/pypoetry/virtualenvs/advanced-pytorch-4G2CGpb3-py3.8/lib/python3.8/site-packages/omegaconf/dictconfig.py", line 442, in _get_impl
    node = self._get_child(
  File "/nfs-share/pa511/.cache/pypoetry/virtualenvs/advanced-pytorch-4G2CGpb3-py3.8/lib/python3.8/site-packages/omegaconf/basecontainer.py", line 73, in _get_child
    child = self._get_node(
  File "/nfs-share/pa511/.cache/pypoetry/virtualenvs/advanced-pytorch-4G2CGpb3-py3.8/lib/python3.8/site-packages/omegaconf/dictconfig.py", line 475, in _get_node
    self._validate_get(key)
  File "/nfs-share/pa511/.cache/pypoetry/virtualenvs/advanced-pytorch-4G2CGpb3-py3.8/lib/python3.8/site-packages/omegaconf/dictconfig.py", line 164, in _validate_get
    self._format_and_raise(
  File "/nfs-share/pa511/.cache/pypoetry/virtualenvs/advanced-pytorch-4G2CGpb3-py3.8/lib/python3.8/site-packages/omegaconf/base.py", line 231, in _format_and_raise
    format_and_raise(
  File "/nfs-share/pa511/.cache/pypoetry/virtualenvs/advanced-pytorch-4G2CGpb3-py3.8/lib/python3.8/site-packages/omegaconf/_utils.py", line 899, in format_and_raise
    _raise(ex, cause)
  File "/nfs-share/pa511/.cache/pypoetry/virtualenvs/advanced-pytorch-4G2CGpb3-py3.8/lib/python3.8/site-packages/omegaconf/_utils.py", line 797, in _raise
    raise ex.with_traceback(sys.exc_info()[2])  # set env var OC_CAUSE=1 for full trace
omegaconf.errors.ConfigAttributeError: Key 'acc' is not in struct
    full_key: method.acc
    object_type=dict

The above exception was the direct cause of the following exception:

[36mray::ClientAppActor.run()[39m (pid=3869578, ip=128.232.115.66, actor_id=31e16f17189adc1fe4af8d3401000000, repr=<flwr.simulation.ray_transport.ray_actor.ClientAppActor object at 0x7f6b68332400>)
  File "/nfs-share/pa511/.cache/pypoetry/virtualenvs/advanced-pytorch-4G2CGpb3-py3.8/lib/python3.8/site-packages/flwr/simulation/ray_transport/ray_actor.py", line 63, in run
    raise ClientAppException(str(ex)) from ex
flwr.client.client_app.ClientAppException: 
Exception ClientAppException occurred. Message: Key 'acc' is not in struct
    full_key: method.acc
    object_type=dict

[91mERROR [0m:     [36mray::ClientAppActor.run()[39m (pid=3869578, ip=128.232.115.66, actor_id=31e16f17189adc1fe4af8d3401000000, repr=<flwr.simulation.ray_transport.ray_actor.ClientAppActor object at 0x7f6b68332400>)
  File "/nfs-share/pa511/.cache/pypoetry/virtualenvs/advanced-pytorch-4G2CGpb3-py3.8/lib/python3.8/site-packages/flwr/client/client_app.py", line 143, in __call__
    return self._call(message, context)
  File "/nfs-share/pa511/.cache/pypoetry/virtualenvs/advanced-pytorch-4G2CGpb3-py3.8/lib/python3.8/site-packages/flwr/client/client_app.py", line 126, in ffn
    out_message = handle_legacy_message_from_msgtype(
  File "/nfs-share/pa511/.cache/pypoetry/virtualenvs/advanced-pytorch-4G2CGpb3-py3.8/lib/python3.8/site-packages/flwr/client/message_handler/message_handler.py", line 120, in handle_legacy_message_from_msgtype
    get_parameters_res = maybe_call_get_parameters(
  File "/nfs-share/pa511/.cache/pypoetry/virtualenvs/advanced-pytorch-4G2CGpb3-py3.8/lib/python3.8/site-packages/flwr/client/client.py", line 214, in maybe_call_get_parameters
    return client.get_parameters(get_parameters_ins)
  File "/nfs-share/pa511/.cache/pypoetry/virtualenvs/advanced-pytorch-4G2CGpb3-py3.8/lib/python3.8/site-packages/flwr/client/numpy_client.py", line 225, in _get_parameters
    parameters = self.numpy_client.get_parameters(config=ins.config)  # type: ignore
  File "/nfs-share/pa511/resnet/client.py", line 87, in get_parameters
    elif self.cfg.method.acc == "quantize":
  File "/nfs-share/pa511/.cache/pypoetry/virtualenvs/advanced-pytorch-4G2CGpb3-py3.8/lib/python3.8/site-packages/omegaconf/dictconfig.py", line 359, in __getattr__
    self._format_and_raise(key=key, value=None, cause=e)
  File "/nfs-share/pa511/.cache/pypoetry/virtualenvs/advanced-pytorch-4G2CGpb3-py3.8/lib/python3.8/site-packages/omegaconf/base.py", line 231, in _format_and_raise
    format_and_raise(
  File "/nfs-share/pa511/.cache/pypoetry/virtualenvs/advanced-pytorch-4G2CGpb3-py3.8/lib/python3.8/site-packages/omegaconf/_utils.py", line 819, in format_and_raise
    _raise(ex, cause)
  File "/nfs-share/pa511/.cache/pypoetry/virtualenvs/advanced-pytorch-4G2CGpb3-py3.8/lib/python3.8/site-packages/omegaconf/_utils.py", line 797, in _raise
    raise ex.with_traceback(sys.exc_info()[2])  # set env var OC_CAUSE=1 for full trace
  File "/nfs-share/pa511/.cache/pypoetry/virtualenvs/advanced-pytorch-4G2CGpb3-py3.8/lib/python3.8/site-packages/omegaconf/dictconfig.py", line 351, in __getattr__
    return self._get_impl(
  File "/nfs-share/pa511/.cache/pypoetry/virtualenvs/advanced-pytorch-4G2CGpb3-py3.8/lib/python3.8/site-packages/omegaconf/dictconfig.py", line 442, in _get_impl
    node = self._get_child(
  File "/nfs-share/pa511/.cache/pypoetry/virtualenvs/advanced-pytorch-4G2CGpb3-py3.8/lib/python3.8/site-packages/omegaconf/basecontainer.py", line 73, in _get_child
    child = self._get_node(
  File "/nfs-share/pa511/.cache/pypoetry/virtualenvs/advanced-pytorch-4G2CGpb3-py3.8/lib/python3.8/site-packages/omegaconf/dictconfig.py", line 475, in _get_node
    self._validate_get(key)
  File "/nfs-share/pa511/.cache/pypoetry/virtualenvs/advanced-pytorch-4G2CGpb3-py3.8/lib/python3.8/site-packages/omegaconf/dictconfig.py", line 164, in _validate_get
    self._format_and_raise(
  File "/nfs-share/pa511/.cache/pypoetry/virtualenvs/advanced-pytorch-4G2CGpb3-py3.8/lib/python3.8/site-packages/omegaconf/base.py", line 231, in _format_and_raise
    format_and_raise(
  File "/nfs-share/pa511/.cache/pypoetry/virtualenvs/advanced-pytorch-4G2CGpb3-py3.8/lib/python3.8/site-packages/omegaconf/_utils.py", line 899, in format_and_raise
    _raise(ex, cause)
  File "/nfs-share/pa511/.cache/pypoetry/virtualenvs/advanced-pytorch-4G2CGpb3-py3.8/lib/python3.8/site-packages/omegaconf/_utils.py", line 797, in _raise
    raise ex.with_traceback(sys.exc_info()[2])  # set env var OC_CAUSE=1 for full trace
omegaconf.errors.ConfigAttributeError: Key 'acc' is not in struct
    full_key: method.acc
    object_type=dict

The above exception was the direct cause of the following exception:

[2024-08-14 20:45:59,910][flwr][ERROR] - [36mray::ClientAppActor.run()[39m (pid=3869578, ip=128.232.115.66, actor_id=31e16f17189adc1fe4af8d3401000000, repr=<flwr.simulation.ray_transport.ray_actor.ClientAppActor object at 0x7f6b68332400>)
  File "/nfs-share/pa511/.cache/pypoetry/virtualenvs/advanced-pytorch-4G2CGpb3-py3.8/lib/python3.8/site-packages/flwr/client/client_app.py", line 143, in __call__
    return self._call(message, context)
  File "/nfs-share/pa511/.cache/pypoetry/virtualenvs/advanced-pytorch-4G2CGpb3-py3.8/lib/python3.8/site-packages/flwr/client/client_app.py", line 126, in ffn
    out_message = handle_legacy_message_from_msgtype(
  File "/nfs-share/pa511/.cache/pypoetry/virtualenvs/advanced-pytorch-4G2CGpb3-py3.8/lib/python3.8/site-packages/flwr/client/message_handler/message_handler.py", line 120, in handle_legacy_message_from_msgtype
    get_parameters_res = maybe_call_get_parameters(
  File "/nfs-share/pa511/.cache/pypoetry/virtualenvs/advanced-pytorch-4G2CGpb3-py3.8/lib/python3.8/site-packages/flwr/client/client.py", line 214, in maybe_call_get_parameters
    return client.get_parameters(get_parameters_ins)
  File "/nfs-share/pa511/.cache/pypoetry/virtualenvs/advanced-pytorch-4G2CGpb3-py3.8/lib/python3.8/site-packages/flwr/client/numpy_client.py", line 225, in _get_parameters
    parameters = self.numpy_client.get_parameters(config=ins.config)  # type: ignore
  File "/nfs-share/pa511/resnet/client.py", line 87, in get_parameters
    elif self.cfg.method.acc == "quantize":
  File "/nfs-share/pa511/.cache/pypoetry/virtualenvs/advanced-pytorch-4G2CGpb3-py3.8/lib/python3.8/site-packages/omegaconf/dictconfig.py", line 359, in __getattr__
    self._format_and_raise(key=key, value=None, cause=e)
  File "/nfs-share/pa511/.cache/pypoetry/virtualenvs/advanced-pytorch-4G2CGpb3-py3.8/lib/python3.8/site-packages/omegaconf/base.py", line 231, in _format_and_raise
    format_and_raise(
  File "/nfs-share/pa511/.cache/pypoetry/virtualenvs/advanced-pytorch-4G2CGpb3-py3.8/lib/python3.8/site-packages/omegaconf/_utils.py", line 819, in format_and_raise
    _raise(ex, cause)
  File "/nfs-share/pa511/.cache/pypoetry/virtualenvs/advanced-pytorch-4G2CGpb3-py3.8/lib/python3.8/site-packages/omegaconf/_utils.py", line 797, in _raise
    raise ex.with_traceback(sys.exc_info()[2])  # set env var OC_CAUSE=1 for full trace
  File "/nfs-share/pa511/.cache/pypoetry/virtualenvs/advanced-pytorch-4G2CGpb3-py3.8/lib/python3.8/site-packages/omegaconf/dictconfig.py", line 351, in __getattr__
    return self._get_impl(
  File "/nfs-share/pa511/.cache/pypoetry/virtualenvs/advanced-pytorch-4G2CGpb3-py3.8/lib/python3.8/site-packages/omegaconf/dictconfig.py", line 442, in _get_impl
    node = self._get_child(
  File "/nfs-share/pa511/.cache/pypoetry/virtualenvs/advanced-pytorch-4G2CGpb3-py3.8/lib/python3.8/site-packages/omegaconf/basecontainer.py", line 73, in _get_child
    child = self._get_node(
  File "/nfs-share/pa511/.cache/pypoetry/virtualenvs/advanced-pytorch-4G2CGpb3-py3.8/lib/python3.8/site-packages/omegaconf/dictconfig.py", line 475, in _get_node
    self._validate_get(key)
  File "/nfs-share/pa511/.cache/pypoetry/virtualenvs/advanced-pytorch-4G2CGpb3-py3.8/lib/python3.8/site-packages/omegaconf/dictconfig.py", line 164, in _validate_get
    self._format_and_raise(
  File "/nfs-share/pa511/.cache/pypoetry/virtualenvs/advanced-pytorch-4G2CGpb3-py3.8/lib/python3.8/site-packages/omegaconf/base.py", line 231, in _format_and_raise
    format_and_raise(
  File "/nfs-share/pa511/.cache/pypoetry/virtualenvs/advanced-pytorch-4G2CGpb3-py3.8/lib/python3.8/site-packages/omegaconf/_utils.py", line 899, in format_and_raise
    _raise(ex, cause)
  File "/nfs-share/pa511/.cache/pypoetry/virtualenvs/advanced-pytorch-4G2CGpb3-py3.8/lib/python3.8/site-packages/omegaconf/_utils.py", line 797, in _raise
    raise ex.with_traceback(sys.exc_info()[2])  # set env var OC_CAUSE=1 for full trace
omegaconf.errors.ConfigAttributeError: Key 'acc' is not in struct
    full_key: method.acc
    object_type=dict

[36mray::ClientAppActor.run()[39m (pid=3869578, ip=128.232.115.66, actor_id=31e16f17189adc1fe4af8d3401000000, repr=<flwr.simulation.ray_transport.ray_actor.ClientAppActor object at 0x7f6b68332400>)
  File "/nfs-share/pa511/.cache/pypoetry/virtualenvs/advanced-pytorch-4G2CGpb3-py3.8/lib/python3.8/site-packages/flwr/simulation/ray_transport/ray_actor.py", line 63, in run
    raise ClientAppException(str(ex)) from ex
flwr.client.client_app.ClientAppException: 
Exception ClientAppException occurred. Message: Key 'acc' is not in struct
    full_key: method.acc
    object_type=dict
The above exception was the direct cause of the following exception:

[36mray::ClientAppActor.run()[39m (pid=3869578, ip=128.232.115.66, actor_id=31e16f17189adc1fe4af8d3401000000, repr=<flwr.simulation.ray_transport.ray_actor.ClientAppActor object at 0x7f6b68332400>)
  File "/nfs-share/pa511/.cache/pypoetry/virtualenvs/advanced-pytorch-4G2CGpb3-py3.8/lib/python3.8/site-packages/flwr/simulation/ray_transport/ray_actor.py", line 63, in run
    raise ClientAppException(str(ex)) from ex
flwr.client.client_app.ClientAppException: 
Exception ClientAppException occurred. Message: Key 'acc' is not in struct
    full_key: method.acc
    object_type=dict
[91mERROR [0m:     [36mray::ClientAppActor.run()[39m (pid=3869578, ip=128.232.115.66, actor_id=31e16f17189adc1fe4af8d3401000000, repr=<flwr.simulation.ray_transport.ray_actor.ClientAppActor object at 0x7f6b68332400>)
  File "/nfs-share/pa511/.cache/pypoetry/virtualenvs/advanced-pytorch-4G2CGpb3-py3.8/lib/python3.8/site-packages/flwr/client/client_app.py", line 143, in __call__
    return self._call(message, context)
  File "/nfs-share/pa511/.cache/pypoetry/virtualenvs/advanced-pytorch-4G2CGpb3-py3.8/lib/python3.8/site-packages/flwr/client/client_app.py", line 126, in ffn
    out_message = handle_legacy_message_from_msgtype(
  File "/nfs-share/pa511/.cache/pypoetry/virtualenvs/advanced-pytorch-4G2CGpb3-py3.8/lib/python3.8/site-packages/flwr/client/message_handler/message_handler.py", line 120, in handle_legacy_message_from_msgtype
    get_parameters_res = maybe_call_get_parameters(
  File "/nfs-share/pa511/.cache/pypoetry/virtualenvs/advanced-pytorch-4G2CGpb3-py3.8/lib/python3.8/site-packages/flwr/client/client.py", line 214, in maybe_call_get_parameters
    return client.get_parameters(get_parameters_ins)
  File "/nfs-share/pa511/.cache/pypoetry/virtualenvs/advanced-pytorch-4G2CGpb3-py3.8/lib/python3.8/site-packages/flwr/client/numpy_client.py", line 225, in _get_parameters
    parameters = self.numpy_client.get_parameters(config=ins.config)  # type: ignore
  File "/nfs-share/pa511/resnet/client.py", line 87, in get_parameters
    elif self.cfg.method.acc == "quantize":
  File "/nfs-share/pa511/.cache/pypoetry/virtualenvs/advanced-pytorch-4G2CGpb3-py3.8/lib/python3.8/site-packages/omegaconf/dictconfig.py", line 359, in __getattr__
    self._format_and_raise(key=key, value=None, cause=e)
  File "/nfs-share/pa511/.cache/pypoetry/virtualenvs/advanced-pytorch-4G2CGpb3-py3.8/lib/python3.8/site-packages/omegaconf/base.py", line 231, in _format_and_raise
    format_and_raise(
  File "/nfs-share/pa511/.cache/pypoetry/virtualenvs/advanced-pytorch-4G2CGpb3-py3.8/lib/python3.8/site-packages/omegaconf/_utils.py", line 819, in format_and_raise
    _raise(ex, cause)
  File "/nfs-share/pa511/.cache/pypoetry/virtualenvs/advanced-pytorch-4G2CGpb3-py3.8/lib/python3.8/site-packages/omegaconf/_utils.py", line 797, in _raise
    raise ex.with_traceback(sys.exc_info()[2])  # set env var OC_CAUSE=1 for full trace
  File "/nfs-share/pa511/.cache/pypoetry/virtualenvs/advanced-pytorch-4G2CGpb3-py3.8/lib/python3.8/site-packages/omegaconf/dictconfig.py", line 351, in __getattr__
    return self._get_impl(
  File "/nfs-share/pa511/.cache/pypoetry/virtualenvs/advanced-pytorch-4G2CGpb3-py3.8/lib/python3.8/site-packages/omegaconf/dictconfig.py", line 442, in _get_impl
    node = self._get_child(
  File "/nfs-share/pa511/.cache/pypoetry/virtualenvs/advanced-pytorch-4G2CGpb3-py3.8/lib/python3.8/site-packages/omegaconf/basecontainer.py", line 73, in _get_child
    child = self._get_node(
  File "/nfs-share/pa511/.cache/pypoetry/virtualenvs/advanced-pytorch-4G2CGpb3-py3.8/lib/python3.8/site-packages/omegaconf/dictconfig.py", line 475, in _get_node
    self._validate_get(key)
  File "/nfs-share/pa511/.cache/pypoetry/virtualenvs/advanced-pytorch-4G2CGpb3-py3.8/lib/python3.8/site-packages/omegaconf/dictconfig.py", line 164, in _validate_get
    self._format_and_raise(
  File "/nfs-share/pa511/.cache/pypoetry/virtualenvs/advanced-pytorch-4G2CGpb3-py3.8/lib/python3.8/site-packages/omegaconf/base.py", line 231, in _format_and_raise
    format_and_raise(
  File "/nfs-share/pa511/.cache/pypoetry/virtualenvs/advanced-pytorch-4G2CGpb3-py3.8/lib/python3.8/site-packages/omegaconf/_utils.py", line 899, in format_and_raise
    _raise(ex, cause)
  File "/nfs-share/pa511/.cache/pypoetry/virtualenvs/advanced-pytorch-4G2CGpb3-py3.8/lib/python3.8/site-packages/omegaconf/_utils.py", line 797, in _raise
    raise ex.with_traceback(sys.exc_info()[2])  # set env var OC_CAUSE=1 for full trace
omegaconf.errors.ConfigAttributeError: Key 'acc' is not in struct
    full_key: method.acc
    object_type=dict

The above exception was the direct cause of the following exception:

[2024-08-14 20:45:59,910][flwr][ERROR] - [36mray::ClientAppActor.run()[39m (pid=3869578, ip=128.232.115.66, actor_id=31e16f17189adc1fe4af8d3401000000, repr=<flwr.simulation.ray_transport.ray_actor.ClientAppActor object at 0x7f6b68332400>)
  File "/nfs-share/pa511/.cache/pypoetry/virtualenvs/advanced-pytorch-4G2CGpb3-py3.8/lib/python3.8/site-packages/flwr/client/client_app.py", line 143, in __call__
    return self._call(message, context)
  File "/nfs-share/pa511/.cache/pypoetry/virtualenvs/advanced-pytorch-4G2CGpb3-py3.8/lib/python3.8/site-packages/flwr/client/client_app.py", line 126, in ffn
    out_message = handle_legacy_message_from_msgtype(
  File "/nfs-share/pa511/.cache/pypoetry/virtualenvs/advanced-pytorch-4G2CGpb3-py3.8/lib/python3.8/site-packages/flwr/client/message_handler/message_handler.py", line 120, in handle_legacy_message_from_msgtype
    get_parameters_res = maybe_call_get_parameters(
  File "/nfs-share/pa511/.cache/pypoetry/virtualenvs/advanced-pytorch-4G2CGpb3-py3.8/lib/python3.8/site-packages/flwr/client/client.py", line 214, in maybe_call_get_parameters
    return client.get_parameters(get_parameters_ins)
  File "/nfs-share/pa511/.cache/pypoetry/virtualenvs/advanced-pytorch-4G2CGpb3-py3.8/lib/python3.8/site-packages/flwr/client/numpy_client.py", line 225, in _get_parameters
    parameters = self.numpy_client.get_parameters(config=ins.config)  # type: ignore
  File "/nfs-share/pa511/resnet/client.py", line 87, in get_parameters
    elif self.cfg.method.acc == "quantize":
  File "/nfs-share/pa511/.cache/pypoetry/virtualenvs/advanced-pytorch-4G2CGpb3-py3.8/lib/python3.8/site-packages/omegaconf/dictconfig.py", line 359, in __getattr__
    self._format_and_raise(key=key, value=None, cause=e)
  File "/nfs-share/pa511/.cache/pypoetry/virtualenvs/advanced-pytorch-4G2CGpb3-py3.8/lib/python3.8/site-packages/omegaconf/base.py", line 231, in _format_and_raise
    format_and_raise(
  File "/nfs-share/pa511/.cache/pypoetry/virtualenvs/advanced-pytorch-4G2CGpb3-py3.8/lib/python3.8/site-packages/omegaconf/_utils.py", line 819, in format_and_raise
    _raise(ex, cause)
  File "/nfs-share/pa511/.cache/pypoetry/virtualenvs/advanced-pytorch-4G2CGpb3-py3.8/lib/python3.8/site-packages/omegaconf/_utils.py", line 797, in _raise
    raise ex.with_traceback(sys.exc_info()[2])  # set env var OC_CAUSE=1 for full trace
  File "/nfs-share/pa511/.cache/pypoetry/virtualenvs/advanced-pytorch-4G2CGpb3-py3.8/lib/python3.8/site-packages/omegaconf/dictconfig.py", line 351, in __getattr__
    return self._get_impl(
  File "/nfs-share/pa511/.cache/pypoetry/virtualenvs/advanced-pytorch-4G2CGpb3-py3.8/lib/python3.8/site-packages/omegaconf/dictconfig.py", line 442, in _get_impl
    node = self._get_child(
  File "/nfs-share/pa511/.cache/pypoetry/virtualenvs/advanced-pytorch-4G2CGpb3-py3.8/lib/python3.8/site-packages/omegaconf/basecontainer.py", line 73, in _get_child
    child = self._get_node(
  File "/nfs-share/pa511/.cache/pypoetry/virtualenvs/advanced-pytorch-4G2CGpb3-py3.8/lib/python3.8/site-packages/omegaconf/dictconfig.py", line 475, in _get_node
    self._validate_get(key)
  File "/nfs-share/pa511/.cache/pypoetry/virtualenvs/advanced-pytorch-4G2CGpb3-py3.8/lib/python3.8/site-packages/omegaconf/dictconfig.py", line 164, in _validate_get
    self._format_and_raise(
  File "/nfs-share/pa511/.cache/pypoetry/virtualenvs/advanced-pytorch-4G2CGpb3-py3.8/lib/python3.8/site-packages/omegaconf/base.py", line 231, in _format_and_raise
    format_and_raise(
  File "/nfs-share/pa511/.cache/pypoetry/virtualenvs/advanced-pytorch-4G2CGpb3-py3.8/lib/python3.8/site-packages/omegaconf/_utils.py", line 899, in format_and_raise
    _raise(ex, cause)
  File "/nfs-share/pa511/.cache/pypoetry/virtualenvs/advanced-pytorch-4G2CGpb3-py3.8/lib/python3.8/site-packages/omegaconf/_utils.py", line 797, in _raise
    raise ex.with_traceback(sys.exc_info()[2])  # set env var OC_CAUSE=1 for full trace
omegaconf.errors.ConfigAttributeError: Key 'acc' is not in struct
    full_key: method.acc
    object_type=dict

[36mray::ClientAppActor.run()[39m (pid=3869578, ip=128.232.115.66, actor_id=31e16f17189adc1fe4af8d3401000000, repr=<flwr.simulation.ray_transport.ray_actor.ClientAppActor object at 0x7f6b68332400>)
  File "/nfs-share/pa511/.cache/pypoetry/virtualenvs/advanced-pytorch-4G2CGpb3-py3.8/lib/python3.8/site-packages/flwr/simulation/ray_transport/ray_actor.py", line 63, in run
    raise ClientAppException(str(ex)) from ex
flwr.client.client_app.ClientAppException: 
Exception ClientAppException occurred. Message: Key 'acc' is not in struct
    full_key: method.acc
    object_type=dict
The above exception was the direct cause of the following exception:

[36mray::ClientAppActor.run()[39m (pid=3869578, ip=128.232.115.66, actor_id=31e16f17189adc1fe4af8d3401000000, repr=<flwr.simulation.ray_transport.ray_actor.ClientAppActor object at 0x7f6b68332400>)
  File "/nfs-share/pa511/.cache/pypoetry/virtualenvs/advanced-pytorch-4G2CGpb3-py3.8/lib/python3.8/site-packages/flwr/simulation/ray_transport/ray_actor.py", line 63, in run
    raise ClientAppException(str(ex)) from ex
flwr.client.client_app.ClientAppException: 
Exception ClientAppException occurred. Message: Key 'acc' is not in struct
    full_key: method.acc
    object_type=dict
[91mERROR [0m:     Traceback (most recent call last):
  File "/nfs-share/pa511/.cache/pypoetry/virtualenvs/advanced-pytorch-4G2CGpb3-py3.8/lib/python3.8/site-packages/flwr/simulation/app.py", line 339, in start_simulation
    hist = run_fl(
  File "/nfs-share/pa511/.cache/pypoetry/virtualenvs/advanced-pytorch-4G2CGpb3-py3.8/lib/python3.8/site-packages/flwr/server/server.py", line 490, in run_fl
    hist, elapsed_time = server.fit(
  File "/nfs-share/pa511/.cache/pypoetry/virtualenvs/advanced-pytorch-4G2CGpb3-py3.8/lib/python3.8/site-packages/flwr/server/server.py", line 93, in fit
    self.parameters = self._get_initial_parameters(server_round=0, timeout=timeout)
  File "/nfs-share/pa511/.cache/pypoetry/virtualenvs/advanced-pytorch-4G2CGpb3-py3.8/lib/python3.8/site-packages/flwr/server/server.py", line 282, in _get_initial_parameters
    get_parameters_res = random_client.get_parameters(
  File "/nfs-share/pa511/.cache/pypoetry/virtualenvs/advanced-pytorch-4G2CGpb3-py3.8/lib/python3.8/site-packages/flwr/simulation/ray_transport/ray_client_proxy.py", line 168, in get_parameters
    message_out = self._submit_job(message, timeout)
  File "/nfs-share/pa511/.cache/pypoetry/virtualenvs/advanced-pytorch-4G2CGpb3-py3.8/lib/python3.8/site-packages/flwr/simulation/ray_transport/ray_client_proxy.py", line 108, in _submit_job
    raise ex
  File "/nfs-share/pa511/.cache/pypoetry/virtualenvs/advanced-pytorch-4G2CGpb3-py3.8/lib/python3.8/site-packages/flwr/simulation/ray_transport/ray_client_proxy.py", line 94, in _submit_job
    out_mssg, updated_context = self.actor_pool.get_client_result(
  File "/nfs-share/pa511/.cache/pypoetry/virtualenvs/advanced-pytorch-4G2CGpb3-py3.8/lib/python3.8/site-packages/flwr/simulation/ray_transport/ray_actor.py", line 398, in get_client_result
    return self._fetch_future_result(cid)
  File "/nfs-share/pa511/.cache/pypoetry/virtualenvs/advanced-pytorch-4G2CGpb3-py3.8/lib/python3.8/site-packages/flwr/simulation/ray_transport/ray_actor.py", line 279, in _fetch_future_result
    res_cid, out_mssg, updated_context = ray.get(
  File "/nfs-share/pa511/.cache/pypoetry/virtualenvs/advanced-pytorch-4G2CGpb3-py3.8/lib/python3.8/site-packages/ray/_private/auto_init_hook.py", line 21, in auto_init_wrapper
    return fn(*args, **kwargs)
  File "/nfs-share/pa511/.cache/pypoetry/virtualenvs/advanced-pytorch-4G2CGpb3-py3.8/lib/python3.8/site-packages/ray/_private/client_mode_hook.py", line 103, in wrapper
    return func(*args, **kwargs)
  File "/nfs-share/pa511/.cache/pypoetry/virtualenvs/advanced-pytorch-4G2CGpb3-py3.8/lib/python3.8/site-packages/ray/_private/worker.py", line 2667, in get
    values, debugger_breakpoint = worker.get_objects(object_refs, timeout=timeout)
  File "/nfs-share/pa511/.cache/pypoetry/virtualenvs/advanced-pytorch-4G2CGpb3-py3.8/lib/python3.8/site-packages/ray/_private/worker.py", line 864, in get_objects
    raise value.as_instanceof_cause()
ray.exceptions.RayTaskError(ClientAppException): [36mray::ClientAppActor.run()[39m (pid=3869578, ip=128.232.115.66, actor_id=31e16f17189adc1fe4af8d3401000000, repr=<flwr.simulation.ray_transport.ray_actor.ClientAppActor object at 0x7f6b68332400>)
  File "/nfs-share/pa511/.cache/pypoetry/virtualenvs/advanced-pytorch-4G2CGpb3-py3.8/lib/python3.8/site-packages/flwr/client/client_app.py", line 143, in __call__
    return self._call(message, context)
  File "/nfs-share/pa511/.cache/pypoetry/virtualenvs/advanced-pytorch-4G2CGpb3-py3.8/lib/python3.8/site-packages/flwr/client/client_app.py", line 126, in ffn
    out_message = handle_legacy_message_from_msgtype(
  File "/nfs-share/pa511/.cache/pypoetry/virtualenvs/advanced-pytorch-4G2CGpb3-py3.8/lib/python3.8/site-packages/flwr/client/message_handler/message_handler.py", line 120, in handle_legacy_message_from_msgtype
    get_parameters_res = maybe_call_get_parameters(
  File "/nfs-share/pa511/.cache/pypoetry/virtualenvs/advanced-pytorch-4G2CGpb3-py3.8/lib/python3.8/site-packages/flwr/client/client.py", line 214, in maybe_call_get_parameters
    return client.get_parameters(get_parameters_ins)
[2024-08-14 20:45:59,915][flwr][ERROR] - Traceback (most recent call last):
  File "/nfs-share/pa511/.cache/pypoetry/virtualenvs/advanced-pytorch-4G2CGpb3-py3.8/lib/python3.8/site-packages/flwr/simulation/app.py", line 339, in start_simulation
    hist = run_fl(
  File "/nfs-share/pa511/.cache/pypoetry/virtualenvs/advanced-pytorch-4G2CGpb3-py3.8/lib/python3.8/site-packages/flwr/server/server.py", line 490, in run_fl
    hist, elapsed_time = server.fit(
  File "/nfs-share/pa511/.cache/pypoetry/virtualenvs/advanced-pytorch-4G2CGpb3-py3.8/lib/python3.8/site-packages/flwr/server/server.py", line 93, in fit
    self.parameters = self._get_initial_parameters(server_round=0, timeout=timeout)
  File "/nfs-share/pa511/.cache/pypoetry/virtualenvs/advanced-pytorch-4G2CGpb3-py3.8/lib/python3.8/site-packages/flwr/server/server.py", line 282, in _get_initial_parameters
    get_parameters_res = random_client.get_parameters(
  File "/nfs-share/pa511/.cache/pypoetry/virtualenvs/advanced-pytorch-4G2CGpb3-py3.8/lib/python3.8/site-packages/flwr/simulation/ray_transport/ray_client_proxy.py", line 168, in get_parameters
    message_out = self._submit_job(message, timeout)
  File "/nfs-share/pa511/.cache/pypoetry/virtualenvs/advanced-pytorch-4G2CGpb3-py3.8/lib/python3.8/site-packages/flwr/simulation/ray_transport/ray_client_proxy.py", line 108, in _submit_job
    raise ex
  File "/nfs-share/pa511/.cache/pypoetry/virtualenvs/advanced-pytorch-4G2CGpb3-py3.8/lib/python3.8/site-packages/flwr/simulation/ray_transport/ray_client_proxy.py", line 94, in _submit_job
    out_mssg, updated_context = self.actor_pool.get_client_result(
  File "/nfs-share/pa511/.cache/pypoetry/virtualenvs/advanced-pytorch-4G2CGpb3-py3.8/lib/python3.8/site-packages/flwr/simulation/ray_transport/ray_actor.py", line 398, in get_client_result
    return self._fetch_future_result(cid)
  File "/nfs-share/pa511/.cache/pypoetry/virtualenvs/advanced-pytorch-4G2CGpb3-py3.8/lib/python3.8/site-packages/flwr/simulation/ray_transport/ray_actor.py", line 279, in _fetch_future_result
    res_cid, out_mssg, updated_context = ray.get(
  File "/nfs-share/pa511/.cache/pypoetry/virtualenvs/advanced-pytorch-4G2CGpb3-py3.8/lib/python3.8/site-packages/ray/_private/auto_init_hook.py", line 21, in auto_init_wrapper
    return fn(*args, **kwargs)
  File "/nfs-share/pa511/.cache/pypoetry/virtualenvs/advanced-pytorch-4G2CGpb3-py3.8/lib/python3.8/site-packages/ray/_private/client_mode_hook.py", line 103, in wrapper
    return func(*args, **kwargs)
  File "/nfs-share/pa511/.cache/pypoetry/virtualenvs/advanced-pytorch-4G2CGpb3-py3.8/lib/python3.8/site-packages/ray/_private/worker.py", line 2667, in get
    values, debugger_breakpoint = worker.get_objects(object_refs, timeout=timeout)
  File "/nfs-share/pa511/.cache/pypoetry/virtualenvs/advanced-pytorch-4G2CGpb3-py3.8/lib/python3.8/site-packages/ray/_private/worker.py", line 864, in get_objects
    raise value.as_instanceof_cause()
ray.exceptions.RayTaskError(ClientAppException): [36mray::ClientAppActor.run()[39m (pid=3869578, ip=128.232.115.66, actor_id=31e16f17189adc1fe4af8d3401000000, repr=<flwr.simulation.ray_transport.ray_actor.ClientAppActor object at 0x7f6b68332400>)
  File "/nfs-share/pa511/.cache/pypoetry/virtualenvs/advanced-pytorch-4G2CGpb3-py3.8/lib/python3.8/site-packages/flwr/client/client_app.py", line 143, in __call__
    return self._call(message, context)
  File "/nfs-share/pa511/.cache/pypoetry/virtualenvs/advanced-pytorch-4G2CGpb3-py3.8/lib/python3.8/site-packages/flwr/client/client_app.py", line 126, in ffn
    out_message = handle_legacy_message_from_msgtype(
  File "/nfs-share/pa511/.cache/pypoetry/virtualenvs/advanced-pytorch-4G2CGpb3-py3.8/lib/python3.8/site-packages/flwr/client/message_handler/message_handler.py", line 120, in handle_legacy_message_from_msgtype
    get_parameters_res = maybe_call_get_parameters(
  File "/nfs-share/pa511/.cache/pypoetry/virtualenvs/advanced-pytorch-4G2CGpb3-py3.8/lib/python3.8/site-packages/flwr/client/client.py", line 214, in maybe_call_get_parameters
  File "/nfs-share/pa511/.cache/pypoetry/virtualenvs/advanced-pytorch-4G2CGpb3-py3.8/lib/python3.8/site-packages/flwr/client/numpy_client.py", line 225, in _get_parameters
    parameters = self.numpy_client.get_parameters(config=ins.config)  # type: ignore
  File "/nfs-share/pa511/resnet/client.py", line 87, in get_parameters
    elif self.cfg.method.acc == "quantize":
  File "/nfs-share/pa511/.cache/pypoetry/virtualenvs/advanced-pytorch-4G2CGpb3-py3.8/lib/python3.8/site-packages/omegaconf/dictconfig.py", line 359, in __getattr__
    self._format_and_raise(key=key, value=None, cause=e)
  File "/nfs-share/pa511/.cache/pypoetry/virtualenvs/advanced-pytorch-4G2CGpb3-py3.8/lib/python3.8/site-packages/omegaconf/base.py", line 231, in _format_and_raise
    format_and_raise(
  File "/nfs-share/pa511/.cache/pypoetry/virtualenvs/advanced-pytorch-4G2CGpb3-py3.8/lib/python3.8/site-packages/omegaconf/_utils.py", line 819, in format_and_raise
    _raise(ex, cause)
  File "/nfs-share/pa511/.cache/pypoetry/virtualenvs/advanced-pytorch-4G2CGpb3-py3.8/lib/python3.8/site-packages/omegaconf/_utils.py", line 797, in _raise
    raise ex.with_traceback(sys.exc_info()[2])  # set env var OC_CAUSE=1 for full trace
  File "/nfs-share/pa511/.cache/pypoetry/virtualenvs/advanced-pytorch-4G2CGpb3-py3.8/lib/python3.8/site-packages/omegaconf/dictconfig.py", line 351, in __getattr__
    return self._get_impl(
  File "/nfs-share/pa511/.cache/pypoetry/virtualenvs/advanced-pytorch-4G2CGpb3-py3.8/lib/python3.8/site-packages/omegaconf/dictconfig.py", line 442, in _get_impl
    node = self._get_child(
  File "/nfs-share/pa511/.cache/pypoetry/virtualenvs/advanced-pytorch-4G2CGpb3-py3.8/lib/python3.8/site-packages/omegaconf/basecontainer.py", line 73, in _get_child
    child = self._get_node(
  File "/nfs-share/pa511/.cache/pypoetry/virtualenvs/advanced-pytorch-4G2CGpb3-py3.8/lib/python3.8/site-packages/omegaconf/dictconfig.py", line 475, in _get_node
    self._validate_get(key)
  File "/nfs-share/pa511/.cache/pypoetry/virtualenvs/advanced-pytorch-4G2CGpb3-py3.8/lib/python3.8/site-packages/omegaconf/dictconfig.py", line 164, in _validate_get
    self._format_and_raise(
  File "/nfs-share/pa511/.cache/pypoetry/virtualenvs/advanced-pytorch-4G2CGpb3-py3.8/lib/python3.8/site-packages/omegaconf/base.py", line 231, in _format_and_raise
    format_and_raise(
  File "/nfs-share/pa511/.cache/pypoetry/virtualenvs/advanced-pytorch-4G2CGpb3-py3.8/lib/python3.8/site-packages/omegaconf/_utils.py", line 899, in format_and_raise
    _raise(ex, cause)
  File "/nfs-share/pa511/.cache/pypoetry/virtualenvs/advanced-pytorch-4G2CGpb3-py3.8/lib/python3.8/site-packages/omegaconf/_utils.py", line 797, in _raise
    raise ex.with_traceback(sys.exc_info()[2])  # set env var OC_CAUSE=1 for full trace
omegaconf.errors.ConfigAttributeError: Key 'acc' is not in struct
    full_key: method.acc
    object_type=dict

The above exception was the direct cause of the following exception:

[36mray::ClientAppActor.run()[39m (pid=3869578, ip=128.232.115.66, actor_id=31e16f17189adc1fe4af8d3401000000, repr=<flwr.simulation.ray_transport.ray_actor.ClientAppActor object at 0x7f6b68332400>)
  File "/nfs-share/pa511/.cache/pypoetry/virtualenvs/advanced-pytorch-4G2CGpb3-py3.8/lib/python3.8/site-packages/flwr/simulation/ray_transport/ray_actor.py", line 63, in run
    raise ClientAppException(str(ex)) from ex
flwr.client.client_app.ClientAppException: 
Exception ClientAppException occurred. Message: Key 'acc' is not in struct
    full_key: method.acc
    object_type=dict

    return client.get_parameters(get_parameters_ins)
  File "/nfs-share/pa511/.cache/pypoetry/virtualenvs/advanced-pytorch-4G2CGpb3-py3.8/lib/python3.8/site-packages/flwr/client/numpy_client.py", line 225, in _get_parameters
    parameters = self.numpy_client.get_parameters(config=ins.config)  # type: ignore
  File "/nfs-share/pa511/resnet/client.py", line 87, in get_parameters
    elif self.cfg.method.acc == "quantize":
  File "/nfs-share/pa511/.cache/pypoetry/virtualenvs/advanced-pytorch-4G2CGpb3-py3.8/lib/python3.8/site-packages/omegaconf/dictconfig.py", line 359, in __getattr__
    self._format_and_raise(key=key, value=None, cause=e)
  File "/nfs-share/pa511/.cache/pypoetry/virtualenvs/advanced-pytorch-4G2CGpb3-py3.8/lib/python3.8/site-packages/omegaconf/base.py", line 231, in _format_and_raise
    format_and_raise(
  File "/nfs-share/pa511/.cache/pypoetry/virtualenvs/advanced-pytorch-4G2CGpb3-py3.8/lib/python3.8/site-packages/omegaconf/_utils.py", line 819, in format_and_raise
    _raise(ex, cause)
  File "/nfs-share/pa511/.cache/pypoetry/virtualenvs/advanced-pytorch-4G2CGpb3-py3.8/lib/python3.8/site-packages/omegaconf/_utils.py", line 797, in _raise
    raise ex.with_traceback(sys.exc_info()[2])  # set env var OC_CAUSE=1 for full trace
  File "/nfs-share/pa511/.cache/pypoetry/virtualenvs/advanced-pytorch-4G2CGpb3-py3.8/lib/python3.8/site-packages/omegaconf/dictconfig.py", line 351, in __getattr__
    return self._get_impl(
  File "/nfs-share/pa511/.cache/pypoetry/virtualenvs/advanced-pytorch-4G2CGpb3-py3.8/lib/python3.8/site-packages/omegaconf/dictconfig.py", line 442, in _get_impl
    node = self._get_child(
  File "/nfs-share/pa511/.cache/pypoetry/virtualenvs/advanced-pytorch-4G2CGpb3-py3.8/lib/python3.8/site-packages/omegaconf/basecontainer.py", line 73, in _get_child
    child = self._get_node(
  File "/nfs-share/pa511/.cache/pypoetry/virtualenvs/advanced-pytorch-4G2CGpb3-py3.8/lib/python3.8/site-packages/omegaconf/dictconfig.py", line 475, in _get_node
    self._validate_get(key)
  File "/nfs-share/pa511/.cache/pypoetry/virtualenvs/advanced-pytorch-4G2CGpb3-py3.8/lib/python3.8/site-packages/omegaconf/dictconfig.py", line 164, in _validate_get
    self._format_and_raise(
  File "/nfs-share/pa511/.cache/pypoetry/virtualenvs/advanced-pytorch-4G2CGpb3-py3.8/lib/python3.8/site-packages/omegaconf/base.py", line 231, in _format_and_raise
    format_and_raise(
  File "/nfs-share/pa511/.cache/pypoetry/virtualenvs/advanced-pytorch-4G2CGpb3-py3.8/lib/python3.8/site-packages/omegaconf/_utils.py", line 899, in format_and_raise
    _raise(ex, cause)
  File "/nfs-share/pa511/.cache/pypoetry/virtualenvs/advanced-pytorch-4G2CGpb3-py3.8/lib/python3.8/site-packages/omegaconf/_utils.py", line 797, in _raise
    raise ex.with_traceback(sys.exc_info()[2])  # set env var OC_CAUSE=1 for full trace
omegaconf.errors.ConfigAttributeError: Key 'acc' is not in struct
    full_key: method.acc
    object_type=dict

The above exception was the direct cause of the following exception:

[36mray::ClientAppActor.run()[39m (pid=3869578, ip=128.232.115.66, actor_id=31e16f17189adc1fe4af8d3401000000, repr=<flwr.simulation.ray_transport.ray_actor.ClientAppActor object at 0x7f6b68332400>)
  File "/nfs-share/pa511/.cache/pypoetry/virtualenvs/advanced-pytorch-4G2CGpb3-py3.8/lib/python3.8/site-packages/flwr/simulation/ray_transport/ray_actor.py", line 63, in run
    raise ClientAppException(str(ex)) from ex
flwr.client.client_app.ClientAppException: 
Exception ClientAppException occurred. Message: Key 'acc' is not in struct
    full_key: method.acc
    object_type=dict

[91mERROR [0m:     Your simulation crashed :(. This could be because of several reasons. The most common are: 
	 > Sometimes, issues in the simulation code itself can cause crashes. It's always a good idea to double-check your code for any potential bugs or inconsistencies that might be contributing to the problem. For example: 
		 - You might be using a class attribute in your clients that hasn't been defined.
		 - There could be an incorrect method call to a 3rd party library (e.g., PyTorch).
		 - The return types of methods in your clients/strategies might be incorrect.
	 > Your system couldn't fit a single VirtualClient: try lowering `client_resources`.
	 > All the actors in your pool crashed. This could be because: 
		 - You clients hit an out-of-memory (OOM) error and actors couldn't recover from it. Try launching your simulation with more generous `client_resources` setting (i.e. it seems {'num_cpus': 2, 'num_gpus': 0.0} is not enough for your run). Use fewer concurrent actors. 
		 - You were running a multi-node simulation and all worker nodes disconnected. The head node might still be alive but cannot accommodate any actor with resources: {'num_cpus': 2, 'num_gpus': 0.0}.
Take a look at the Flower simulation examples for guidance <https://flower.ai/docs/framework/how-to-run-simulations.html>.
[2024-08-14 20:45:59,915][flwr][ERROR] - Your simulation crashed :(. This could be because of several reasons. The most common are: 
	 > Sometimes, issues in the simulation code itself can cause crashes. It's always a good idea to double-check your code for any potential bugs or inconsistencies that might be contributing to the problem. For example: 
		 - You might be using a class attribute in your clients that hasn't been defined.
		 - There could be an incorrect method call to a 3rd party library (e.g., PyTorch).
		 - The return types of methods in your clients/strategies might be incorrect.
	 > Your system couldn't fit a single VirtualClient: try lowering `client_resources`.
	 > All the actors in your pool crashed. This could be because: 
		 - You clients hit an out-of-memory (OOM) error and actors couldn't recover from it. Try launching your simulation with more generous `client_resources` setting (i.e. it seems {'num_cpus': 2, 'num_gpus': 0.0} is not enough for your run). Use fewer concurrent actors. 
		 - You were running a multi-node simulation and all worker nodes disconnected. The head node might still be alive but cannot accommodate any actor with resources: {'num_cpus': 2, 'num_gpus': 0.0}.
Take a look at the Flower simulation examples for guidance <https://flower.ai/docs/framework/how-to-run-simulations.html>.
Error executing job with overrides: []
Traceback (most recent call last):
  File "/nfs-share/pa511/.cache/pypoetry/virtualenvs/advanced-pytorch-4G2CGpb3-py3.8/lib/python3.8/site-packages/flwr/simulation/app.py", line 339, in start_simulation
    hist = run_fl(
  File "/nfs-share/pa511/.cache/pypoetry/virtualenvs/advanced-pytorch-4G2CGpb3-py3.8/lib/python3.8/site-packages/flwr/server/server.py", line 490, in run_fl
    hist, elapsed_time = server.fit(
  File "/nfs-share/pa511/.cache/pypoetry/virtualenvs/advanced-pytorch-4G2CGpb3-py3.8/lib/python3.8/site-packages/flwr/server/server.py", line 93, in fit
    self.parameters = self._get_initial_parameters(server_round=0, timeout=timeout)
  File "/nfs-share/pa511/.cache/pypoetry/virtualenvs/advanced-pytorch-4G2CGpb3-py3.8/lib/python3.8/site-packages/flwr/server/server.py", line 282, in _get_initial_parameters
    get_parameters_res = random_client.get_parameters(
  File "/nfs-share/pa511/.cache/pypoetry/virtualenvs/advanced-pytorch-4G2CGpb3-py3.8/lib/python3.8/site-packages/flwr/simulation/ray_transport/ray_client_proxy.py", line 168, in get_parameters
    message_out = self._submit_job(message, timeout)
  File "/nfs-share/pa511/.cache/pypoetry/virtualenvs/advanced-pytorch-4G2CGpb3-py3.8/lib/python3.8/site-packages/flwr/simulation/ray_transport/ray_client_proxy.py", line 108, in _submit_job
    raise ex
  File "/nfs-share/pa511/.cache/pypoetry/virtualenvs/advanced-pytorch-4G2CGpb3-py3.8/lib/python3.8/site-packages/flwr/simulation/ray_transport/ray_client_proxy.py", line 94, in _submit_job
    out_mssg, updated_context = self.actor_pool.get_client_result(
  File "/nfs-share/pa511/.cache/pypoetry/virtualenvs/advanced-pytorch-4G2CGpb3-py3.8/lib/python3.8/site-packages/flwr/simulation/ray_transport/ray_actor.py", line 398, in get_client_result
    return self._fetch_future_result(cid)
  File "/nfs-share/pa511/.cache/pypoetry/virtualenvs/advanced-pytorch-4G2CGpb3-py3.8/lib/python3.8/site-packages/flwr/simulation/ray_transport/ray_actor.py", line 279, in _fetch_future_result
    res_cid, out_mssg, updated_context = ray.get(
  File "/nfs-share/pa511/.cache/pypoetry/virtualenvs/advanced-pytorch-4G2CGpb3-py3.8/lib/python3.8/site-packages/ray/_private/auto_init_hook.py", line 21, in auto_init_wrapper
    return fn(*args, **kwargs)
  File "/nfs-share/pa511/.cache/pypoetry/virtualenvs/advanced-pytorch-4G2CGpb3-py3.8/lib/python3.8/site-packages/ray/_private/client_mode_hook.py", line 103, in wrapper
    return func(*args, **kwargs)
  File "/nfs-share/pa511/.cache/pypoetry/virtualenvs/advanced-pytorch-4G2CGpb3-py3.8/lib/python3.8/site-packages/ray/_private/worker.py", line 2667, in get
    values, debugger_breakpoint = worker.get_objects(object_refs, timeout=timeout)
  File "/nfs-share/pa511/.cache/pypoetry/virtualenvs/advanced-pytorch-4G2CGpb3-py3.8/lib/python3.8/site-packages/ray/_private/worker.py", line 864, in get_objects
    raise value.as_instanceof_cause()
ray.exceptions.RayTaskError(ClientAppException): [36mray::ClientAppActor.run()[39m (pid=3869578, ip=128.232.115.66, actor_id=31e16f17189adc1fe4af8d3401000000, repr=<flwr.simulation.ray_transport.ray_actor.ClientAppActor object at 0x7f6b68332400>)
  File "/nfs-share/pa511/.cache/pypoetry/virtualenvs/advanced-pytorch-4G2CGpb3-py3.8/lib/python3.8/site-packages/flwr/client/client_app.py", line 143, in __call__
    return self._call(message, context)
  File "/nfs-share/pa511/.cache/pypoetry/virtualenvs/advanced-pytorch-4G2CGpb3-py3.8/lib/python3.8/site-packages/flwr/client/client_app.py", line 126, in ffn
    out_message = handle_legacy_message_from_msgtype(
  File "/nfs-share/pa511/.cache/pypoetry/virtualenvs/advanced-pytorch-4G2CGpb3-py3.8/lib/python3.8/site-packages/flwr/client/message_handler/message_handler.py", line 120, in handle_legacy_message_from_msgtype
    get_parameters_res = maybe_call_get_parameters(
  File "/nfs-share/pa511/.cache/pypoetry/virtualenvs/advanced-pytorch-4G2CGpb3-py3.8/lib/python3.8/site-packages/flwr/client/client.py", line 214, in maybe_call_get_parameters
    return client.get_parameters(get_parameters_ins)
  File "/nfs-share/pa511/.cache/pypoetry/virtualenvs/advanced-pytorch-4G2CGpb3-py3.8/lib/python3.8/site-packages/flwr/client/numpy_client.py", line 225, in _get_parameters
    parameters = self.numpy_client.get_parameters(config=ins.config)  # type: ignore
  File "/nfs-share/pa511/resnet/client.py", line 87, in get_parameters
    elif self.cfg.method.acc == "quantize":
  File "/nfs-share/pa511/.cache/pypoetry/virtualenvs/advanced-pytorch-4G2CGpb3-py3.8/lib/python3.8/site-packages/omegaconf/dictconfig.py", line 359, in __getattr__
    self._format_and_raise(key=key, value=None, cause=e)
  File "/nfs-share/pa511/.cache/pypoetry/virtualenvs/advanced-pytorch-4G2CGpb3-py3.8/lib/python3.8/site-packages/omegaconf/base.py", line 231, in _format_and_raise
    format_and_raise(
  File "/nfs-share/pa511/.cache/pypoetry/virtualenvs/advanced-pytorch-4G2CGpb3-py3.8/lib/python3.8/site-packages/omegaconf/_utils.py", line 819, in format_and_raise
    _raise(ex, cause)
  File "/nfs-share/pa511/.cache/pypoetry/virtualenvs/advanced-pytorch-4G2CGpb3-py3.8/lib/python3.8/site-packages/omegaconf/_utils.py", line 797, in _raise
    raise ex.with_traceback(sys.exc_info()[2])  # set env var OC_CAUSE=1 for full trace
  File "/nfs-share/pa511/.cache/pypoetry/virtualenvs/advanced-pytorch-4G2CGpb3-py3.8/lib/python3.8/site-packages/omegaconf/dictconfig.py", line 351, in __getattr__
    return self._get_impl(
  File "/nfs-share/pa511/.cache/pypoetry/virtualenvs/advanced-pytorch-4G2CGpb3-py3.8/lib/python3.8/site-packages/omegaconf/dictconfig.py", line 442, in _get_impl
    node = self._get_child(
  File "/nfs-share/pa511/.cache/pypoetry/virtualenvs/advanced-pytorch-4G2CGpb3-py3.8/lib/python3.8/site-packages/omegaconf/basecontainer.py", line 73, in _get_child
    child = self._get_node(
  File "/nfs-share/pa511/.cache/pypoetry/virtualenvs/advanced-pytorch-4G2CGpb3-py3.8/lib/python3.8/site-packages/omegaconf/dictconfig.py", line 475, in _get_node
    self._validate_get(key)
  File "/nfs-share/pa511/.cache/pypoetry/virtualenvs/advanced-pytorch-4G2CGpb3-py3.8/lib/python3.8/site-packages/omegaconf/dictconfig.py", line 164, in _validate_get
    self._format_and_raise(
  File "/nfs-share/pa511/.cache/pypoetry/virtualenvs/advanced-pytorch-4G2CGpb3-py3.8/lib/python3.8/site-packages/omegaconf/base.py", line 231, in _format_and_raise
    format_and_raise(
  File "/nfs-share/pa511/.cache/pypoetry/virtualenvs/advanced-pytorch-4G2CGpb3-py3.8/lib/python3.8/site-packages/omegaconf/_utils.py", line 899, in format_and_raise
    _raise(ex, cause)
  File "/nfs-share/pa511/.cache/pypoetry/virtualenvs/advanced-pytorch-4G2CGpb3-py3.8/lib/python3.8/site-packages/omegaconf/_utils.py", line 797, in _raise
    raise ex.with_traceback(sys.exc_info()[2])  # set env var OC_CAUSE=1 for full trace
omegaconf.errors.ConfigAttributeError: Key 'acc' is not in struct
    full_key: method.acc
    object_type=dict

The above exception was the direct cause of the following exception:

[36mray::ClientAppActor.run()[39m (pid=3869578, ip=128.232.115.66, actor_id=31e16f17189adc1fe4af8d3401000000, repr=<flwr.simulation.ray_transport.ray_actor.ClientAppActor object at 0x7f6b68332400>)
  File "/nfs-share/pa511/.cache/pypoetry/virtualenvs/advanced-pytorch-4G2CGpb3-py3.8/lib/python3.8/site-packages/flwr/simulation/ray_transport/ray_actor.py", line 63, in run
    raise ClientAppException(str(ex)) from ex
flwr.client.client_app.ClientAppException: 
Exception ClientAppException occurred. Message: Key 'acc' is not in struct
    full_key: method.acc
    object_type=dict

The above exception was the direct cause of the following exception:

Traceback (most recent call last):
  File "main.py", line 63, in main
    history = fl.simulation.start_simulation(
  File "/nfs-share/pa511/.cache/pypoetry/virtualenvs/advanced-pytorch-4G2CGpb3-py3.8/lib/python3.8/site-packages/flwr/simulation/app.py", line 375, in start_simulation
    raise RuntimeError("Simulation crashed.") from ex
RuntimeError: Simulation crashed.

Set the environment variable HYDRA_FULL_ERROR=1 for a complete stack trace.
srun: error: ngongotaha: task 0: Exited with exit code 1
